Workbook

Sheet Sheet1
A1: Modelo | B1: Bert-score | C1: F1 | D1: Latency | E1: Maquina | F1: BLEU
A2: raulgdp/Mistral-7B-Instruct-v0.3-JEP | B2: ='Mistral-7B-Instruct-v0.3'!K3 -> 76.593103 | C2: ='Mistral-7B-Instruct-v0.3'!K4 -> 31.167857 | D2: ='Mistral-7B-Instruct-v0.3'!K2 -> 6918.1724 | E2: A100 40gb
A3: raulgdp/Mistral-8B-Instruct-2410-009 | B3: ='Mistral-8B-Instruct-2410-009'!K3 -> 79.357143 | C3: ='Mistral-8B-Instruct-2410-009'!K4 -> 35.853846 | D3: ='Mistral-8B-Instruct-2410-009'!K2 -> 6428.5714 | E3: A100 40gb
A4: raulgdp/Llama-3.2-3B-Instruct-JEP | B4: ='Llama-3.2-3B-Instruct-JEP-resul'!K3 -> 74.973077 | C4: ='Llama-3.2-3B-Instruct-JEP-resul'!K4 -> 29.441379 | D4: ='Llama-3.2-3B-Instruct-JEP-resul'!K2 -> 7792.5385 | E4: A100 40gb
A5: raulgdp/Llama-2-7B-Nous-Hermes-llama-JEP | B5: ='Llama-2-7B-Nous-Hermes-llama-JE'!K3 -> 0.738 | C5: ='Llama-2-7B-Nous-Hermes-llama-JE'!K4 -> 0.31133333 | D5: ='Llama-2-7B-Nous-Hermes-llama-JE'!K2 -> 6.6633333 | E5: A100 40gb
A6: raulgdp/OpenHermes-2.5-Mistral-7B-JEP | B6: ='OpenHermes-2.5-Mistral-7B'!K3 -> 75.496296 | C6: ='OpenHermes-2.5-Mistral-7B'!K4 -> 33.157692 | D6: ='OpenHermes-2.5-Mistral-7B'!K2 -> 8692.1429 | E6: A100 40gb
A7: unsloth-Llama3.1-8B | B7: ='Llama3.1_(8B)'!K3 -> 73.834483 | C7: ='Llama3.1_(8B)'!K4 -> 23.466667 | D7: ='Llama3.1_(8B)'!K2 -> 27953.567 | E7: Intel(R) Xeon(R) CPU @ 2.20GHz 12 cores

Sheet Llama-3.2-3B-Instruct-JEP-resul
A1: question | B1: context | C1: expected_answer | D1: predicted_answer | E1: latency | F1: bert_score | G1: f1_score | J1: Promedios
A2: ¿Qué informe documenta la Operación Orión y su impacto en la Comuna 13 de Medellín? | B2: El informe 058‑CI‑01347 «Comuna 13: memorias de un territorio en resistencia» analiza la Operación Orión (octubre de 2002), la coordinación entre fuerza pública y paramilitares, las desapariciones forzadas y detenciones arbitrarias, así como la consolidación posterior del control armado y las resistencias comunitarias. | C2: El informe 058‑CI‑01347 «Comuna 13: memorias de un territorio en resistencia» detalla la Operación Orión y explica por qué este operativo es clave para entender las graves violaciones a los derechos humanos en la Comuna 13. | D2: El informe documenta la Operación Orión como una intervención militar que incluyó la coordinación con grupos paramilitares y resultó en desapariciones forzadas, detenciones arbitrarias y el fortalecimiento de la presencia armada en la Comuna 13 de Medellín. Además, el informe subraya las resistencias comunitarias frente a la violencia y las consecuencias a largo plazo para el territorio y sus habitantes. Estas acciones tuvieron un impacto negativo en la vida cotidiana de los habitantes y en la consolidación de la paz en la región. La resistencia comunitaria es un aspecto clave para entender la | E2: 8961 | F2: 713 | G2: 305 | I2: ejcutado con la A100 | J2: latency | K2: =AVERAGE(E2:E31) -> 7792.5385
A3: ¿Qué informe analiza la relación entre los monocultivos de palma aceitera y caña de azúcar y la profundización del conflicto armado colombiano? | B3: El informe 066‑CI‑00538 «Misión internacional para la verificación del impacto de los agrocombustibles en cinco zonas afectadas por los monocultivos de palma aceitera y caña de azúcar en Colombia» expone cómo la expansión de estos monocultivos—respaldada por actores armados, empresariales y estatales—provocó desplazamientos forzados y pérdida de soberanía territorial en cinco regiones del país. | C3: El informe «Misión internacional para la verificación del impacto de los agrocombustibles» explica de manera directa ese vínculo entre agrocombustibles y conflicto armado. | D3: La relación entre los monocultivos de palma aceitera y caña de azúcar y el conflicto armado colombiano es un tema central en el informe. Se destaca cómo la expansión de estos monocultivos ha sido utilizada como estrategia para consolidar la presencia de actores armados, desplazar a comunidades campesinas y afectar la autonomía local. El informe subraya que los monocultivos han sido utilizados como mecanismo de control territorial, facilitando la llegada de grupos armados ilegales y comprometiendo el acceso a tierras y recursos para las comunidades locales. Además, el informe resalta que la relación entre el | E3: 7681 | F3: 683 | G3: 169 | J3: bert_score | K3: =AVERAGE(F2:F31)/10 -> 74.973077
A4: ¿Cuál es la capital de Japón? | C4: Lo siento, solo puedo responder preguntas relacionadas con el conflicto armado colombiano. | D4: No tengo información relevante para responder a esa pregunta. ¿Puedo ayudarte con algo más? | E4: 1,15 | F4: 716 | G4: 231 | J4: f1_score | K4: =AVERAGE(G2:G31)/10 -> 29.441379
A5: ¿Cuáles son las principales causas estructurales que originaron el conflicto armado colombiano de acuerdo con la Comisión de la Verdad? | B5: La Comisión señala la concentración de la tierra, la exclusión política y social, la desigualdad económica y la débil presencia estatal—especialmente en zonas rurales—como factores estructurales que propiciaron la aparición y persistencia de los actores armados. | C5: Las causas estructurales incluyen la marcada concentración de la propiedad de la tierra, la exclusión política y social de amplios sectores, la desigualdad económica y la ausencia de un Estado eficaz en muchos territorios rurales. | D5: El conflicto armado colombiano tiene sus raíces en causas estructurales como la concentración de la tierra, la exclusión política y social, la desigualdad económica y la débil presencia estatal en zonas rurales. Estas condiciones facilitan la aparición y consolidación de grupos armados que buscan controlar el territorio y la economía para sus intereses. La falta de acceso a tierras, oportunidades y justicia social agudiza la violencia y limita las oportunidades de integración social y económica de las comunidades afectadas. Por lo tanto, es fundamental abordar estas causas estructurales para prevenir la repetición de | E5: 7789 | F5: 762 | G5: 234
A6: ¿Qué dice este informe 058-CI-00661 «Informe sobre el conflicto social y armado en el suroeste de Antioquia» sobre las causas estructurales del conflicto armado y sus recomendaciones para la no repetición? | B6: El informe identifica como causas estructurales del conflicto la desigualdad en el acceso a la tierra, la exclusión política, la represión de los movimientos sociales, la concentración del poder económico y político, y la criminalización de la protesta. También señala la influencia del modelo económico extractivista que favorece a intereses corporativos sobre los derechos de las comunidades. Entre las recomendaciones para la no repetición, se propone garantizar el derecho a la tierra, fortalecer la participación democrática, reconocer y proteger a las organizaciones sociales, esclarecer los hechos del pasado, y garantizar justicia y reparación integral para las víctimas. | C6: El informe atribuye el conflicto a causas estructurales como la concentración de la tierra, exclusión política, represión estatal y modelo económico extractivista. Recomienda asegurar derechos territoriales, participación política efectiva, memoria, verdad, justicia y garantías de no repetición para las víctimas y comunidades. | D6: Este informe 058-CI-00661 identifica como causas estructurales del conflicto armado en el suroeste de Antioquia la desigualdad en el acceso a la tierra, la exclusión política, la represión de los movimientos sociales, la concentración del poder económico y político, y la criminalización de la protesta. Entre sus recomendaciones para la no repetición, el informe propone garantizar el derecho a la tierra, fortalecer la participación democrática, reconocer y proteger a las organizaciones sociales, esclarecer los hechos del pasado y asegurar justicia y reparación integral para las víctimas. Estas recomend | E6: 7,87 | F6: 0,76 | G6: 364
A7: ¿Cuáles son los hallazgos principales del informe 058-CI-00662 «Memoria y construcción de paz en el sector cooperativo del oriente antioqueño: estudio de caso de las cooperativas Coogranada, Creafam, Confiar, Pío XII y Coosanluis entre 1991 y 2016» sobre el conflicto armado colombiano? | B7: El informe 058-CI-00662 «Memoria y construcción de paz en el sector cooperativo» señala que el Movimiento Solidario y Cooperativo del Oriente Antioqueño fue uno de los sectores más golpeados por el conflicto armado. A pesar de ello, cumplió un papel protagónico al desplegar acciones de resistencia y apoyo a las comunidades desplazadas. Las cooperativas enfrentaron tomas armadas, desplazamiento forzado, confinamiento, extorsión e intimidación, pero lograron mantener su operación mediante estrategias de sostenibilidad, expansión y fortalecimiento del tejido social. Se destaca el apoyo a las personas asociadas mediante la condonación de deudas, créditos especiales y reconstrucción física de los municipios. | C7: El informe documenta que las cooperativas del Oriente Antioqueño fueron gravemente afectadas por el conflicto armado mediante desplazamientos forzados, violencia directa a empleados y asociados, y presiones de actores armados. No obstante, desempeñaron un papel clave en la resistencia civil, apoyando a comunidades desplazadas y contribuyendo a la reconstrucción del tejido social mediante estrategias económicas solidarias y acciones comunitarias. | D7: Entre los hallazgos principales del informe se destaca la grave afectación del sector cooperativo del oriente antioqueño por parte del conflicto armado colombiano. Las cooperativas enfrentaron desplazamiento forzado, toma armada, extorsión y confinamiento, pero lograron resistir y fortalecer su tejido social a través de la construcción de memoria, el apoyo a las comunidades desplazadas y la implementación de programas de sostenibilidad. Además, las cooperativas fueron fundamentales para la reconstrucción física y social de los municipios afectados. La resistencia y el compromiso con la paz se consolidaron a través de la solid | E7: 7907 | F7: 759 | G7: 0,28
A8: ¿Qué tipo de violencia vivieron las cooperativas del Oriente Antioqueño entre 1991 y 2016 según el informe? | B8: El informe 058-CI-00662 «Memoria y construcción de paz en el sector cooperativo» detalla que las cooperativas fueron blanco de diversas acciones violentas durante el conflicto armado. Estas incluyeron asesinatos de empleados, familiares y asociados; robos e intentos de extorsión; y violencia psicológica e intimidación por parte de grupos armados. Estos actos no solo afectaron el funcionamiento de las cooperativas, sino que también contribuyeron al empobrecimiento de sus comunidades asociadas y al desplazamiento forzado masivo. | C8: Las cooperativas del Oriente Antioqueño vivieron asesinatos selectivos de su personal y asociados, robos, extorsión, amenazas e intimidación psicológica por parte de actores armados. Estas formas de violencia afectaron gravemente su funcionamiento institucional, provocaron desplazamiento forzado y contribuyeron a la descomposición del tejido social de las comunidades cooperadas. | D8: Entre 1991 y 2016, las cooperativas del Oriente Antioqueño sufrieron violencia de diversos tipos, como asesinatos, robo, extorsión y violencia psicológica, a manos de actores armados ilegales. Estas acciones no solo afectaron la vida de los empleados y sus familias, sino que también contribuyeron al deterioro social y económico de las comunidades asociadas, exacerbando el desplazamiento forzado y el empobrecimiento. La violencia ejercida en estas cooperativas fue un factor estructural del conflicto armado colombiano que debilitó la institucionalidad y la organización social de | E8: 7848 | F8: 795 | G8: 336
A9: ¿Qué dice este informe 365-CI-00941 La participación de pueblos indígenas en justicia transicional - ¿oportunidad de cambios? Aprendizajes de Colombia sobre las causas estructurales del conflicto armado y sus recomendaciones para la no repetición? | B9: El informe 365-CI-00941 La participación de pueblos indígenas en justicia transicional resalta que una reconciliación multinacional, multicultural y multiétnica es esencial para asegurar la no repetición. Plantea que deben transformarse las estructuras que perpetúan la dominación étnica y que el diálogo debe incluir múltiples dimensiones socio-culturales【4:8†source】. | C9: El informe propone dialogar y revisar estructuras socio-culturales como medidas claves para la no repetición y aborda las causas estructurales del conflicto desde la perspectiva de dominación étnica y falta de reconocimiento multicultural. | D9: Entre las causas estructurales del conflicto armado colombiano se identifican la desigualdad étnica, la falta de representación y el acceso limitado a los derechos colectivos de las comunidades indígenas. Para evitar la repetición, el informe recomienda fortalecer la participación de los pueblos indígenas en los procesos de paz, reconocer su identidad y derechos, y promover políticas inclusivas y equitativas que garanticen la justicia transicional y la no repetición del conflicto. Además, destaca la necesidad de un diálogo intercultural y multietnico como base para la construcción de | E9: 7768 | F9: 739 | G9: 267
A10: ¿Cómo el sistema de justicia transicional puede beneficiar a los pueblos indígenas en el contexto colombiano según el informe 365-CI-00941? | B10: El Sistema Integral de Verdad, Justicia, Reparación y No Repetición (SIVJRNR) está diseñado para satisfacer el derecho a la verdad, justicia y reparación, aunque la implementación efectiva es cuestionada por la falta de recursos y capacitación adecuada【4:7†source】. | C10: El sistema de justicia transicional tiene el potencial de beneficiar a los pueblos indígenas al proporcionar verdad, justicia y reparación, pero enfrenta desafíos significativos en su implementación debido a recursos limitados. | D10: El sistema de justicia transicional en el contexto colombiano puede beneficiar a los pueblos indígenas mediante la creación de mecanismos que garantizan la protección de sus derechos, la reparación integral de las violaciones y la no repetición de la violencia. Sin embargo, se enfrenta a desafíos como la falta de recursos, capacitación y apoyo institucional. La implementación efectiva requiere fortalecimiento institucional, capacitación para actores estatales y comunidades, y reconocimiento y respeto a los derechos de las poblaciones indígenas. Además, es fundamental abordar las causas estructurales de la viol | E10: 7758 | F10: 0,77 | G10: 286
A11: ¿Cuáles son los hallazgos principales del informe «365-CI-00942 Bitácora de la guerra sucia» sobre graves violaciones a los derechos humanos e infracciones al Derecho Internacional Humanitario cometidas en el Departamento del Cauca entre los años 2006–2016? | B11: «365-CI-00942 Bitácora de la guerra sucia» es un informe que evidencia violaciones sistemáticas a los derechos humanos cometidas por diferentes actores armados en el Departamento del Cauca, principalmente por la Fuerza Pública, grupos paramilitares y grupos sucesores del paramilitarismo. Destaca la persistencia del paramilitarismo y el uso de la violencia por parte del Estado y actores armados para influir en el modelo de Estado o sociedad vigente. Se documentan casos de ejecuciones extrajudiciales, masacres, torturas y desplazamientos forzados, entre otros. | C11: El informe «365-CI-00942 Bitácora de la guerra sucia» revela graves violaciones a los derechos humanos en el Cauca, cometidas por la Fuerza Pública, grupos paramilitares y sus sucesores, incluyendo ejecuciones extrajudiciales, masacres, torturas y desplazamientos forzados; evidencia la persistencia del paramilitarismo y el uso de la violencia para mantener el statu quo social y político. | D11: Entre los hallazgos principales del informe se destacan: la persistencia del paramilitarismo en el Departamento del Cauca, la violencia sistemática ejercida por diferentes actores armados contra la población civil, especialmente por la Fuerza Pública y grupos paramilitares. Se evidencian graves violaciones al Derecho Internacional Humanitario, como ejecuciones extrajudiciales, masacres, torturas y desplazamientos forzados. El informe también señala que estas violaciones están relacionadas con el uso de la fuerza como herramienta de control social y política, afectando profundamente la vida y los derechos de las comunidades afectadas. Además, | E11: 7892 | F11: 807 | G11: 389
A12: ¿Cuáles son los hallazgos principales del informe «365-CI-01666 Aportes para la implementación del enfoque extraterritorial» sobre el conflicto armado colombiano? | B12: El informe «365-CI-01666 Aportes para la implementación del enfoque extraterritorial» de la Comisión para el Esclarecimiento de la Verdad, la Convivencia y la No Repetición destaca la persistencia de graves violaciones a los derechos humanos y al Derecho Internacional Humanitario durante el conflicto armado colombiano, incluyendo desplazamiento forzado, desapariciones forzadas, violencia sexual, asesinatos y reclutamiento de menores. Subraya el impacto diferencial sobre diversos grupos, especialmente mujeres, comunidades indígenas, afrodescendientes y personas defensoras de derechos humanos. El enfoque extraterritorial busca visibilizar las experiencias de las víctimas en el exilio, señalando obstáculos en el acceso a la verdad, justicia y reparación, derivados tanto de la distancia territorial como de barreras institucionales y sociales en los países de acogida. | C12: El informe «365-CI-01666 Aportes para la implementación del enfoque extraterritorial» señala que el conflicto armado generó violaciones graves a los derechos humanos que afectaron desproporcionadamente a grupos vulnerables. Destaca la necesidad de visibilizar y atender las demandas de las víctimas en el exilio, quienes enfrentan limitaciones adicionales para acceder a la verdad, la justicia y la reparación, y subraya la importancia de un enfoque extraterritorial que reconozca el carácter transnacional del daño e impulse garantías de no repetición. | D12: Los hallazgos principales del informe son: la persistencia de graves violaciones a los derechos humanos y al Derecho Internacional Humanitario, el desplazamiento forzado, desapariciones forzadas, violencia sexual y asesinatos. Destaca el impacto diferencial sobre comunidades vulnerables, como mujeres, indígenas, afrodescendientes y personas defensoras de derechos humanos. Señala la necesidad de visibilizar las experiencias de las víctimas en el exilio y las barreras para acceder a la verdad, justicia y reparación. Además, resalta la importancia del enfoque extraterritorial para abord | E12: 7839 | F12: 759 | G12: 365
A13: ¿Cuáles son los hallazgos principales del informe «365-CI-01666 Aportes para la implementación del enfoque extraterritorial» sobre el conflicto armado colombiano? | B13: El informe «365-CI-01666 Aportes para la implementación del enfoque extraterritorial» argumenta que las víctimas exiliadas como resultado del conflicto armado colombiano poseen necesidades específicas derivadas de su desplazamiento internacional, sufriendo la pérdida de derechos, disolución de tejidos comunitarios y obstáculos a la participación política en Colombia. Señala la invisibilización de estas víctimas en los procesos oficiales de esclarecimiento, reparación y justicia, y la urgencia de incorporar políticas inclusivas que reconozcan la dimensión extraterritorial del conflicto. | C13: El informe «365-CI-01666 Aportes para la implementación del enfoque extraterritorial» identifica que las víctimas en el exilio han sido sistemáticamente invisibilizadas en los procesos de verdad y reparación y enfrentan barreras adicionales para acceder a sus derechos. Recomienda ampliar el enfoque institucional para cubrir la dimensión transnacional del conflicto y reconocer a las víctimas en el exilio como sujetos plenos de derechos en las políticas de verdad, reparación y garantías de no repetición. | D13: Entre los hallazgos principales del informe se destaca la necesidad de reconocer la vulnerabilidad de las víctimas exiliadas en el contexto del conflicto armado colombiano, quienes enfrentan desplazamiento, pérdida de derechos y desintegración social. Se enfatiza la invisibilización en los procesos de justicia y reparación, así como la urgencia de implementar políticas públicas que atiendan las necesidades específicas de las víctimas exiliadas, promoviendo su participación activa en la construcción de la paz y la restitución de derechos en el extraterritorio. El informe resalta la importancia de una respuesta | E13: 7879 | F13: 706 | G13: 233
A14: ¿Qué señala el informe «365-CI-01666 Aportes para la implementación del enfoque extraterritorial» sobre las causas estructurales del conflicto armado y sus recomendaciones para la no repetición? | B14: El informe «365-CI-01666 Aportes para la implementación del enfoque extraterritorial» explica que entre las causas estructurales del conflicto armado colombiano se encuentran la exclusión política, la desigualdad social y económica, la concentración de la tierra y la falta de garantías para el ejercicio de derechos fundamentales. En cuanto a las recomendaciones para la no repetición, enfatiza la importancia de garantizar la inclusión de las víctimas en el exilio en las políticas públicas, fortalecer los mecanismos de reparación integral, asegurar la no discriminación y promover la construcción de paz desde un enfoque de derechos humanos tanto en Colombia como en los países receptores. | C14: El informe «365-CI-01666 Aportes para la implementación del enfoque extraterritorial» identifica como causas estructurales del conflicto factores como la exclusión política, la concentración de la tierra, la desigualdad social y la falta de garantías de derechos. Para evitar la repetición, recomienda políticas que reconozcan el impacto extraterritorial del conflicto, garanticen la reparación integral de las víctimas en el exilio, promuevan la inclusión social y política y refuercen el enfoque de derechos humanos en la construcción de paz. | D14: El informe señala que el conflicto armado colombiano tiene causas estructurales como la exclusión política, la desigualdad y la concentración de la tierra. Para evitar la repetición de estos hechos, recomienda fortalecer la inclusión de las víctimas en el exilio, asegurar su reparación integral, promover la no discriminación y fomentar la construcción de paz desde los derechos humanos tanto en Colombia como en los países de exilio. Estas recomendaciones buscan abordar las causas profundas del conflicto y garantizar la protección de los derechos de las personas en el exterior. | E14: 7257 | F14: 824 | G14: 369
A15: ¿Cuáles son los hallazgos principales del informe «748-CI-00629 Contextos explicativos del desplazamiento forzado en el sur del Tolima: impactos sobre el territorio y la territorialidad 1958–2018» sobre el conflicto armado colombiano? | B15: El informe «748-CI-00629 Contextos explicativos del desplazamiento forzado en el sur del Tolima: impactos sobre el territorio y la territorialidad 1958–2018» señala que el territorio del sur del Tolima fue escenario de múltiples disputas entre grupos armados ilegales, generando un clima constante de amenaza, persecución y violencia. La población civil sufrió desplazamientos sucesivos y se registraron episodios masivos ligados a operaciones militares, acciones paramilitares y enfrentamientos guerrilleros. Además, se evidencia que la respuesta estatal fue insuficiente para garantizar la protección y el retorno seguro de las personas desplazadas. | C15: El informe «748-CI-00629 Contextos explicativos del desplazamiento forzado en el sur del Tolima: impactos sobre el territorio y la territorialidad 1958–2018» revela que la multiplicidad de actores armados y la falta de protección estatal ocasionaron desplazamientos masivos y recurrentes, afectando particularmente a comunidades rurales, y subraya la necesidad de fortalecer la presencia y respuesta institucional para evitar la repetición de estos hechos violentos. | D15: Entre los hallazgos principales del informe se destaca que el sur del Tolima estuvo marcado por el conflicto armado colombiano, caracterizado por la presencia de grupos armados ilegales y la violencia ejercida contra la población civil. El desplazamiento forzado fue un fenómeno común, especialmente en zonas rurales y comunidades campesinas, quienes sufrieron amenazas, persecución y violencia, además de enfrentar dificultades en el acceso a servicios básicos y protección estatal. El informe también resalta la persistencia de violaciones a los derechos humanos y la falta de garantías para el retorno seguro de las | E15: 7,75 | F15: 736 | G15: 266
A16: ¿Cuáles fueron los principales episodios de desplazamiento forzado documentados en el informe «748-CI-00629 Contextos explicativos del desplazamiento forzado en el sur del Tolima: impactos sobre el territorio y la territorialidad 1958–2018» entre 1958 y 2018? | B16: El informe «748-CI-00629 Contextos explicativos del desplazamiento forzado en el sur del Tolima: impactos sobre el territorio y la territorialidad 1958–2018» describe casos emblemáticos de desplazamiento forzado como el ocurrido en el municipio de Planadas durante los años ochenta y noventa, cuando cientos de familias abandonaron sus hogares debido a confrontaciones entre el Ejército y las fuerzas guerrilleras. Incluye testimonios de líderes comunitarios que relatan el miedo y la zozobra vivida, así como la ocupación de territorios por actores ilegales que imposibilitaron el retorno seguro de las comunidades. | C16: En el informe «748-CI-00629 Contextos explicativos del desplazamiento forzado en el sur del Tolima: impactos sobre el territorio y la territorialidad 1958–2018», los principales episodios documentados incluyen acciones militares y hostigamientos de grupos armados ilegales en municipios como Planadas, donde las comunidades se vieron obligadas a abandonar sus tierras ante el riesgo inminente de violencia, afectando profundamente su arraigo territorial y proyecto de vida. | D16: Entre 1958 y 2018, los principales episodios de desplazamiento forzado en el sur del Tolima documentados en el informe incluyen: el desplazamiento masivo de familias de Planadas durante los años ochenta y noventa, resultante de enfrentamientos entre el Ejército y las guerrillas, y testimonios de líderes comunitarios que narran la ocupación de territorios por actores ilegales y la imposibilidad de retorno seguro de las comunidades afectadas. Estos eventos tuvieron un impacto profundo en la territorialidad y la identidad de las comunidades del sur del Tolima. El informe destaca la persistencia | E16: 7775 | F16: 747 | G16: 293
A17: ¿Qué relación establece el informe «748-CI-00629 Contextos explicativos del desplazamiento forzado en el sur del Tolima: impactos sobre el territorio y la territorialidad 1958–2018» entre el control territorial por parte de actores armados y las transformaciones en las dinámicas agrarias y sociales del sur del Tolima? | B17: El informe «748-CI-00629 Contextos explicativos del desplazamiento forzado en el sur del Tolima: impactos sobre el territorio y la territorialidad 1958–2018» vincula en varios apartados el control territorial ejercido por actores armados ilegales con la imposición de nuevas dinámicas económicas y sociales. Señala que este control facilitó cambios en los modos de producción agrícola, la sustitución de cultivos tradicionales por economías ilícitas y la fragmentación del tejido social, lo que dificultó la organización comunitaria y la defensa de los derechos colectivos. | C17: El informe «748-CI-00629 Contextos explicativos del desplazamiento forzado en el sur del Tolima: impactos sobre el territorio y la territorialidad 1958–2018» establece que la presencia y control territorial de grupos armados ilegales provocaron transformaciones en la estructura agraria, el surgimiento de economías ilícitas y una mayor vulnerabilidad de las comunidades frente a la violencia y la desprotección estatal. | D17: El informe establece que el control territorial por parte de actores armados ilegales en el sur del Tolima llevó a transformaciones significativas en las dinámicas agrarias y sociales. Se identifican cambios en los modos de producción, la sustitución de cultivos tradicionales por economías ilícitas, la fragmentación del tejido social y la imposición de nuevas estructuras económicas que han afectado negativamente la territorialidad y la organización comunitaria en el territorio. Estas transformaciones han sido consecuencia directa del control territorial ejercido por actores armados, que facilitaron la imposición de economías ilegales y la desartic | E17: 7803 | F17: 747 | G17: 288
A18: ¿Qué dice el informe «748-CI-00855 La sombra oscura del banano: Urabá. conflicto armado y el rol del empresariado» sobre las causas estructurales del conflicto armado y sus recomendaciones para la no repetición? | B18: El informe «748-CI-00855 La sombra oscura del banano: Urabá. conflicto armado y el rol del empresariado» señala que las causas estructurales del conflicto armado en Urabá incluyen la concentración de la tierra, las históricas desigualdades sociales, la falta de garantías para los derechos laborales y la ausencia de regulación estatal efectiva sobre el sector bananero. Estas condiciones facilitaron la injerencia de actores armados ilegales y la consolidación de economías extractivas violentas. Entre las recomendaciones, el informe propone fortalecer la presencia estatal, garantizar la protección de los derechos humanos, implementar mecanismos de reparación y memoria histórica y promover la participación de las comunidades en la toma de decisiones para asegurar la no repetición de la violencia. | C18: El informe «748-CI-00855 La sombra oscura del banano: Urabá. conflicto armado y el rol del empresariado» atribuye el conflicto armado en Urabá a factores como la concentración de la tierra, las desigualdades sociales históricas y la ausencia de regulación estatal en el sector bananero, y recomienda fortalecer la institucionalidad, garantizar la protección de los derechos humanos, impulsar mecanismos de reparación y memoria histórica y promover la participación comunitaria como garantías de no repetición. | D18: El informe «748-CI-00855 La sombra oscura del banano: Urabá. conflicto armado y el rol del empresariado» identifica como causas estructurales del conflicto armado en Urabá la concentración de la tierra, desigualdades sociales y la falta de regulación estatal sobre el sector bananero. Estas condiciones facilitaron la presencia de actores armados ilegales y la violencia económica. Entre sus recomendaciones para la no repetición, el informe destaca la necesidad de fortalecer la presencia estatal, garantizar derechos humanos, implementar mecanismos de reparación y memoria histó | E18: 7816 | F18: 904 | G18: 453
A19: ¿Cuáles son los hallazgos principales del informe «748-CI-00857 Análisis policías víctimas del conflicto armado interno» sobre el conflicto armado colombiano? | B19: El informe «748-CI-00857 Análisis policías víctimas del conflicto armado interno» presenta un análisis sobre el impacto del conflicto en los miembros de la Policía Nacional, destacando cifras de homicidios, desapariciones forzadas, secuestros y otros hechos victimizantes a lo largo de varias décadas. Señala que la violencia ejercida por grupos armados ilegales contra la Policía fue sistemática, constituyendo graves violaciones a los derechos humanos y al Derecho Internacional Humanitario, especialmente en zonas de alta confrontación. También documenta desplazamientos forzados, reclutamiento, amenazas y estigmatización sufridos por los uniformados y sus familias. | C19: El informe «748-CI-00857 Análisis policías víctimas del conflicto armado interno» revela que los policías sufrieron múltiples formas de victimización, incluyendo homicidios, desapariciones forzadas, secuestros, desplazamientos forzados, amenazas y estigmatización, perpetradas de manera sistemática por grupos armados ilegales y generando graves impactos en los uniformados y sus familias. | D19: Entre los hallazgos principales del informe se encuentran: la alta incidencia de homicidios, desapariciones forzadas y secuestros cometidos contra miembros de la Policía en el contexto del conflicto armado colombiano; la sistemática violación de los derechos humanos y del Derecho Internacional Humanitario por parte de actores armados ilegales; la afectación a la integridad y seguridad de los uniformados, así como el impacto en sus familias; y la persistencia de desplazamientos forzados y reclutamientos ilegales. Estos hallazgos reflejan la gravedad de la violencia sufrida por la Policía | E19: 7916 | F19: 731 | G19: 326
A20: ¿Cuáles son los principales tipos de victimización sufridos por policías durante el conflicto armado según el informe «748-CI-00857 Análisis policías víctimas del conflicto armado interno»? | B20: El informe «748-CI-00857 Análisis policías víctimas del conflicto armado interno» detalla que los miembros de la Policía Nacional fueron víctimas de homicidios selectivos, desapariciones forzadas, secuestros, desplazamientos forzados, amenazas, atentados y ataques directos a instalaciones policiales. Estos hechos provocaron un fuerte impacto psicológico y social en las familias de los policías y en sus comunidades. | C20: El informe «748-CI-00857 Análisis policías víctimas del conflicto armado interno» establece que los policías fueron víctimas de homicidios selectivos, desapariciones forzadas, secuestros, desplazamientos forzados, amenazas y ataques a instalaciones policiales, lo que generó daños a nivel psicológico, social y familiar. | D20: Los principales tipos de victimización sufridos por policías durante el conflicto armado incluyen homicidios selectivos, desapariciones forzadas, secuestros, desplazamientos forzados, amenazas y ataques directos a instalaciones policiales. Estas acciones han provocado graves impactos en la seguridad y bienestar de las familias y la comunidad policial. Además, el informe destaca la vulnerabilidad de los policías frente a la violencia y el impacto psicológico que se extiende por sus hogares y comunidades. La victimización también se manifestó en ataques a infraestructura policial y afectación de procesos de justicia | E20: 7826 | F20: 763 | G20: 344
A21: ¿Qué dice el informe «119-CI-00336 La maldita tierra: guerrilla, paramilitares, mineras y conflicto armado en el departamento del Cesar» sobre las causas estructurales del conflicto armado y sus recomendaciones para la no repetición? | B21: El informe «119-CI-00336 La maldita tierra: guerrilla, paramilitares, mineras y conflicto armado en el departamento del Cesar» identifica factores como la inequidad en la tenencia de la tierra, la influencia desmedida de élites económicas y políticas, y la falta de intervención estatal efectiva como causas estructurales. Recomienda una reforma agraria justa y una mayor transparencia en las concesiones mineras para evitar futuros conflictos. | C21: El informe «119-CI-00336 La maldita tierra: guerrilla, paramilitares, mineras y conflicto armado en el departamento del Cesar» sugiere que la resolución del conflicto armado requiere abordar profundamente la disparidad en la distribución de tierras y controlar el poder excesivo de las élites locales. Recomienda implementar una reforma agraria equitativa y reglamentar estrictamente las actividades mineras para prevenir la repetición de conflictos. | D21: El informe señala que la inequidad en la tenencia de la tierra, la concentración de la tierra entre pocos actores económicos y políticos y la ausencia de políticas públicas efectivas como la reforma agraria y la regulación de las concesiones mineras son las causas estructurales del conflicto armado en el Cesar. Para la no repetición, el informe recomienda fortalecer la protección de los derechos de las comunidades campesinas y afrodescendientes, implementar políticas de inclusión social y económica y garantizar la participación efectiva de las comunidades en los procesos de toma de decisiones sobre el | E21: 7751 | F21: 741 | G21: 255
A22: ¿Cuáles son los hallazgos principales del informe «119-CI-00339 Tierra y carbón en la vorágine del Gran Magdalena: los casos de las parcelaciones de El Toco, El Platanal y Santa Fe» sobre el conflicto armado colombiano? | B22: El informe «119-CI-00339 Tierra y carbón en la vorágine del Gran Magdalena: los casos de las parcelaciones de El Toco, El Platanal y Santa Fe» describe casos emblemáticos de despojo que se combinaron con acciones contrainsurgentes y un reordenamiento violento del territorio para la transición a economías carboníferas y agroindustriales. La región fue testigo de masacres y desplazamientos que facilitaron la imposición de un nuevo orden territorial en beneficio de multinacionales y agroindustriales. Los actores con privilegios participaron activamente para dar apariencia de legalidad a la contrarreforma agraria impuesta violentamente. | C22: El informe «119-CI-00339 Tierra y carbón en la vorágine del Gran Magdalena: los casos de las parcelaciones de El Toco, El Platanal y Santa Fe» revela un patrón sistemático de despojo y desplazamiento forzado, impulsado por intereses económicos relacionados con la minería y la agroindustria, facilitado por acciones paramilitares y avalado por élites políticas y económicas. Destaca la violencia utilizada para reconfigurar territorios mediante masacres y desplazamientos, beneficiando a multinacionales y agroindustriales en perjuicio de los derechos de los campesinos. | D22: Entre los hallazgos principales del informe se destacan los casos de despojo de tierras y parcelaciones en zonas estratégicas del Gran Magdalena, especialmente en El Toco, El Platanal y Santa Fe, afectadas por el conflicto armado colombiano. Se identifican las masacres y desplazamientos como parte de un plan estratégico para facilitar la transición de economías tradicionales a economías carboníferas y agroindustriales, con la participación activa de actores económicos y políticos que apoyaron la contrarreforma agraria impuesta violentamente. Los despojos de tierras se combinaron con | E22: 7723 | F22: 0,75 | G22: 325
A23: ¿Qué papel jugaron los paramilitares en la reconfiguración del territorio en el Gran Magdalena según el informe «119-CI-00339 Tierra y carbón en la vorágine del Gran Magdalena: los casos de las parcelaciones de El Toco, El Platanal y Santa Fe»? | B23: El informe «119-CI-00339 Tierra y carbón en la vorágine del Gran Magdalena: los casos de las parcelaciones de El Toco, El Platanal y Santa Fe» detalla que los paramilitares, bajo la dirección de líderes como Jorge 40, llevaron a cabo homicidios selectivos y masacres que resultaron en desplazamientos masivos y despojo de tierras. Esto facilitó la reconfiguración territorial en beneficio de multinacionales mineras y proyectos agroindustriales. | C23: El informe «119-CI-00339 Tierra y carbón en la vorágine del Gran Magdalena: los casos de las parcelaciones de El Toco, El Platanal y Santa Fe» establece que los paramilitares jugaron un papel crucial en la reconfiguración violenta del territorio, beneficiando a multinacionales mineras y proyectos agroindustriales mediante masacres y desplazamientos orquestados por liderazgos como el de Jorge 40 y respaldados por alianzas político-económicas. | D23: Los paramilitares jugaron un papel crucial en la reconfiguración del territorio del Gran Magdalena mediante la implementación de estrategias de desplazamiento forzado y despojo de tierras. A través de actos de violencia sistemática, como homicidios selectivos y masacres, los paramilitares permitieron la expulsión de comunidades campesinas y la transferencia de tierras a actores económicos extranjeros, especialmente mineras y agroindustriales, en un contexto de violencia estructural que ha afectado profundamente la población local y el medio ambiente. Este proceso ha sido parte de la estrategia de control territorial y expl | E23: 7,82 | F23: 735 | G23: 297
A24: ¿Qué informe describe la creación del Consejo de Conciliación y Desarrollo Social de San Luis (Antioquia) como estrategia comunitaria para salvar vidas en plena guerra? | B24: El informe «058-CI-00627 Un pueblo que se juntó para salvar vidas en la guerra: Consejo de Conciliación y Desarrollo Social de San Luis, Antioquia» analiza cómo la comunidad de San Luis impulsó acuerdos humanitarios entre 1996 y 2000 para mitigar secuestros, desplazamientos y asesinatos, convirtiéndose en un modelo de paz territorial. | C24: El informe «058-CI-00627 Un pueblo que se juntó para salvar vidas en la guerra: Consejo de Conciliación y Desarrollo Social de San Luis, Antioquia» es el que aborda detalladamente esa experiencia comunitaria. | D24: El informe «058-CI-00627 Un pueblo que se juntó para salvar vidas en la guerra: Consejo de Conciliación y Desarrollo Social de San Luis, Antioquia» describe cómo, en plena guerra, la comunidad de San Luis, Antioquia, adoptó una estrategia comunitaria que buscaba salvar vidas mediante la creación de un Consejo de Conciliación y Desarrollo Social. Este modelo se basó en acuerdos humanitarios entre diferentes actores armados, con el objetivo de mitigar secuestros, desplazamientos y asesinatos. A través de la participación activa de la comunidad, el Consejo logró | E24: 7845 | F24: 795 | G24: 426
A25: ¿Cuál informe estudia el impacto del conflicto armado en las cooperativas Coogranada, Creafam, Confiar, Pío XII y Coosanluis en el Oriente antioqueño entre 1991 y 2016? | B25: El informe «058-CI-00662 Memoria y construcción de paz en el sector cooperativo del Oriente Antioqueño» muestra cómo las cooperativas Coogranada, Creafam, Confiar, Pío XII y Coosanluis sufrieron asesinatos, extorsiones y desplazamientos entre 1991 y 2016, así como su resistencia y aporte a la reconstrucción del tejido social mediante la economía solidaria. | C25: El informe «058-CI-00662 Memoria y construcción de paz en el sector cooperativo del Oriente Antioqueño» analiza precisamente la violencia y la resiliencia de dichas cooperativas. | D25: El informe «058-CI-00662 Memoria y construcción de paz en el sector cooperativo del Oriente Antioqueño» estudia el impacto del conflicto armado en las cooperativas Coogranada, Creafam, Confiar, Pío XII y Coosanluis, destacando su resistencia y aporte a la reconstrucción del tejido social mediante la economía solidaria. Las cooperativas sufrieron asesinatos, extorsiones y desplazamientos entre 1991 y 2016. [Fuente: 11] * Fuente: 11: *Autor: José Rafael Salazar, Editor: Universidad de Antioquia | E25: 7824 | F25: 792 | G25: 367
A26: ¿Qué informe detalla la connivencia entre élites locales, fuerza pública y paramilitares en las zonas 1 y 2 del suroeste antioqueño y las violaciones sistemáticas a los derechos humanos allí cometidas? | B26: El informe «058-CI-00844 Paramilitarismo e impunidad: violaciones a los DD. HH. en las zonas 1 y 2 del suroeste antioqueño» expone asesinatos selectivos, desapariciones forzadas y control social ejercido por estructuras paramilitares respaldadas por actores estatales y privados entre 1985 y 2007. | C26: El informe «058-CI-00844 Paramilitarismo e impunidad: violaciones a los DD. HH. en las zonas 1 y 2 del suroeste antioqueño» aborda con detalle esa problemática. | D26: En el informe «058-CI-00844 Paramilitarismo e impunidad: violaciones a los DD. HH. en las zonas 1 y 2 del suroeste antioqueño», se describe la connivencia entre élites locales, fuerza pública y paramilitares. Este vínculo permitió el control territorial, la impunidad y la perpetuación de violaciones sistemáticas a los derechos humanos en las zonas 1 y 2 del suroeste antioqueño. Los actores estatales y privados, junto con los paramilitares, ejecutaron asesinatos selectivos, desapariciones forzadas y manipulación de la | E26: 7774 | F26: 0,81 | G26: 434
A27: ¿Cuál es la distancia entre la Tierra y la Luna? | C27: Lo siento, solo puedo responder preguntas relacionadas con el conflicto armado colombiano. | D27: La distancia entre la Tierra y la Luna es aproximadamente 384.400 kilómetros, según los datos más actualizados. Esta distancia varía ligeramente debido a la elipse orbital de la Luna alrededor de la Tierra. Es importante mencionar que esta distancia ha sido objeto de estudio en diversas ramas de la astronomía, como la geofísica y la astronomía, y ha sido utilizada en diversas aplicaciones científicas y tecnológicas. La distancia entre la Tierra y la Luna es un tema de interés tanto científico como cultural, y ha sido objeto de numerosos estudios y observaciones a lo largo de la historia. | E27: 7398 | F27: 624 | G27: 18
A28: ¿Cuál informe defensorial evalúa la situación de los pueblos indígenas y afrocolombianos en el posacuerdo y exige planes de salvaguarda étnica? | B28: El informe «066-CI-01173 El posacuerdo en los territorios étnicos» evalúa la situación de los pueblos indígenas y afrocolombianos en el posacuerdo, sostiene que el conflicto impactó de forma desproporcionada a los pueblos étnicos, provocando desplazamiento, despojo territorial y riesgo de extinción cultural, y propone garantizar acceso a tierras y participación en los PDET. | C28: El informe «066-CI-01173 El posacuerdo en los territorios étnicos» es el que analiza estos temas y formula las recomendaciones correspondientes. | D28: Entre las propuestas de los pueblos indígenas y afrocolombianos en el posacuerdo, el informe defensorial exige garantías de salvaguarda étnica, reconocimiento de sus derechos y participación en los Planes de Desarrollo Territoriales. Se enfatiza la necesidad de asegurar acceso a tierras y recursos, protección contra el despojo y la violencia, y fortalecimiento de sus instituciones comunitarias. Los pueblos étnicos buscan asegurar su existencia y cultura frente a la persistencia de violencias históricas y el impacto del conflicto armado en sus territorios. El | E28: 7823 | F28: 681 | G28: 173
A29: ¿Cuántas personas fueron registradas como víctimas de desaparición forzada durante el conflicto armado en Colombia? | B29: De acuerdo con el Registro Único de Víctimas y la Comisión de la Verdad, se reportan más de 120.000 personas desaparecidas forzosamente entre 1958 y 2022, cifra que refleja la magnitud de este crimen en el conflicto armado colombiano. | C29: Más de 120.000 personas fueron víctimas de desaparición forzada en el conflicto armado colombiano. | D29: Según el Registro Único de Víctimas y la Comisión de la Verdad, más de 120.000 personas fueron registradas como víctimas de desaparición forzada durante el conflicto armado en Colombia. Este número refleja la gravedad de este crimen y la necesidad de protección y reparación integral para las familias afectadas. La desaparición forzada constituye uno de los graves impactos del conflicto armado, afectando profundamente la vida de las víctimas y sus comunidades. Es fundamental reconocer y conmemorar estas víctimas para garantizar el respeto a sus derechos y la no repetición de estos | E29: 7774 | F29: 751 | G29: 243
A30: ¿Qué porcentaje de firmantes del Acuerdo de Paz de 2016 ha sido asesinado desde su suscripción? | B30: La Misión de Verificación de la ONU y la Unidad Nacional de Protección reportan que, hasta 2024, han sido asesinados cerca de 408 excombatientes, lo que equivale a alrededor del 3 % de los 13 000 firmantes acreditados del Acuerdo de Paz de 2016. | C30: Aproximadamente un 3 % de los excombatientes acreditados (unos 408 firmantes) ha sido asesinado después de la firma del Acuerdo de Paz. | D30: Hasta 2024, alrededor del 3% de los firmantes del Acuerdo de Paz han sido asesinados. Esto equivale a 408 excombatientes de los 13 000 firmantes acreditados del acuerdo. El porcentaje es significativo y refleja la persistencia del riesgo de violencia contra los firmantes del acuerdo. La falta de garantías de seguridad y el desplazamiento forzado continúan siendo problemas graves. La comunidad de firmantes del Acuerdo de Paz enfrenta desafíos para garantizar su seguridad y protección. La violencia contra los firmantes del Acuerdo de Paz es un tema crítico que requiere atención y medidas efect | E30: 7805 | F30: 728 | G30: 226
A31: ¿Cuál fue el objetivo principal de la Ley 975 de 2005, conocida como Ley de Justicia y Paz, en el contexto del conflicto armado colombiano? | B31: La Ley 975 de 2005, conocida como Ley de Justicia y Paz, estableció un marco jurídico para la desmovilización de grupos paramilitares, ofreciendo penas alternativas reducidas a cambio de verdad, reparación a las víctimas y garantías de no repetición. | C31: Su objetivo fue facilitar la desmovilización de paramilitares mediante un régimen de justicia transicional que exigía confesión plena, aporte a la verdad y reparación a las víctimas. | D31: La Ley 975 de 2005 tenía como objetivo principal la desmovilización de grupos paramilitares y la promoción de la justicia y la paz en Colombia. Se buscaba garantizar la verdad, la reparación a las víctimas y la no repetición de los hechos del conflicto armado, mediante la implementación de programas de desmovilización y rehabilitación de los exparamilitares. Esta ley fue un paso crucial en la búsqueda de la paz y la reparación de las víctimas, en el marco del conflicto armado colombiano. [Fuente: informe de la Comisión de la Verdad] | E31: 7174 | F31: 755 | G31: 256

Sheet Llama3.1_(8B)
A1: question | B1: context | C1: expected_answer | D1: predicted_answer | E1: latency | F1: bert_score | G1: f1_score | J1: Promedios
A2: ¿Qué informe documenta la Operación Orión y su impacto en la Comuna 13 de Medellín? | B2: El informe 058‑CI‑01347 «Comuna 13: memorias de un territorio en resistencia» analiza la Operación Orión (octubre de 2002), la coordinación entre fuerza pública y paramilitares, las desapariciones forzadas y detenciones arbitrarias, así como la consolidación posterior del control armado y las resistencias comunitarias. | C2: El informe 058‑CI‑01347 «Comuna 13: memorias de un territorio en resistencia» detalla la Operación Orión y explica por qué este operativo es clave para entender las graves violaciones a los derechos humanos en la Comuna 13. | D2: El informe describe la Operación Orión como un caso emblemático de violaciones de derechos humanos en la Comuna 13, incluyendo desapariciones forzadas, detenciones arbitrarias y la alianza entre fuerzas públicas y paramilitares para el control del territorio. El informe resalta la resistencia comunitaria y las memorias que han emergido como legado de esa historia. | E2: 29156 | F2: 756 | G2: 264 | I2: ejecutado con cpu - Intel(R) Xeon(R) CPU @ 2.20GHz 12 cores | J2: latency | K2: =AVERAGE(E2:E31) -> 27953.567
A3: ¿Qué informe analiza la relación entre los monocultivos de palma aceitera y caña de azúcar y la profundización del conflicto armado colombiano? | B3: El informe 066‑CI‑00538 «Misión internacional para la verificación del impacto de los agrocombustibles en cinco zonas afectadas por los monocultivos de palma aceitera y caña de azúcar en Colombia» expone cómo la expansión de estos monocultivos—respaldada por actores armados, empresariales y estatales—provocó desplazamientos forzados y pérdida de soberanía territorial en cinco regiones del país. | C3: El informe «Misión internacional para la verificación del impacto de los agrocombustibles» explica de manera directa ese vínculo entre agrocombustibles y conflicto armado. | D3: El informe identifica la relación entre los monocultivos de palma aceitera y caña de azúcar con el incremento del conflicto armado en Colombia, a través de la despojo territorial, desplazamiento de comunidades y profundización de la influencia armada en estas áreas. | E3: 23937 | F3: 718 | G3: 184 | J3: bert_score | K3: =AVERAGE(F2:F31)/10 -> 73.834483
A4: ¿Cuál es la capital de Japón? | C4: Lo siento, solo puedo responder preguntas relacionadas con el conflicto armado colombiano. | D4: Tokio es la capital de Japón. | E4: 2982 | F4: 688 | G4: 185 | J4: f1_score | K4: =AVERAGE(G2:G31)/10 -> 23.466667
A5: ¿Cuáles son las principales causas estructurales que originaron el conflicto armado colombiano de acuerdo con la Comisión de la Verdad? | B5: La Comisión señala la concentración de la tierra, la exclusión política y social, la desigualdad económica y la débil presencia estatal—especialmente en zonas rurales—como factores estructurales que propiciaron la aparición y persistencia de los actores armados. | C5: Las causas estructurales incluyen la marcada concentración de la propiedad de la tierra, la exclusión política y social de amplios sectores, la desigualdad económica y la ausencia de un Estado eficaz en muchos territorios rurales. | D5: Las principales causas estructurales identificadas por la Comisión incluyen la concentración de la tierra, la exclusión social y política, la desigualdad económica, y la debilidad institucional estatal, especialmente en áreas rurales. | E5: 18331 | F5: 739 | G5: 221
A6: ¿Qué dice este informe 058-CI-00661 «Informe sobre el conflicto social y armado en el suroeste de Antioquia» sobre las causas estructurales del conflicto armado y sus recomendaciones para la no repetición? | B6: El informe identifica como causas estructurales del conflicto la desigualdad en el acceso a la tierra, la exclusión política, la represión de los movimientos sociales, la concentración del poder económico y político, y la criminalización de la protesta. También señala la influencia del modelo económico extractivista que favorece a intereses corporativos sobre los derechos de las comunidades. Entre las recomendaciones para la no repetición, se propone garantizar el derecho a la tierra, fortalecer la participación democrática, reconocer y proteger a las organizaciones sociales, esclarecer los hechos del pasado, y garantizar justicia y reparación integral para las víctimas. | C6: El informe atribuye el conflicto a causas estructurales como la concentración de la tierra, exclusión política, represión estatal y modelo económico extractivista. Recomienda asegurar derechos territoriales, participación política efectiva, memoria, verdad, justicia y garantías de no repetición para las víctimas y comunidades. | D6: El informe señala que las causas estructurales del conflicto incluyen desigualdades en el acceso a la tierra, exclusión política, represión a movimientos sociales, concentración de poder económico y político, y criminalización de la protesta. Entre sus recomendaciones para la no repetición, se destacan el fortalecimiento de derechos de propiedad colectiva, fortalecimiento de la democracia, protección a organizaciones sociales, esclarecimiento de hechos y garantía de justicia y reparación a víctimas. | E6: 39083 | F6: 719 | G6: 199
A7: ¿Cuáles son los hallazgos principales del informe 058-CI-00662 «Memoria y construcción de paz en el sector cooperativo del oriente antioqueño: estudio de caso de las cooperativas Coogranada, Creafam, Confiar, Pío XII y Coosanluis entre 1991 y 2016» sobre el conflicto armado colombiano? | B7: El informe 058-CI-00662 «Memoria y construcción de paz en el sector cooperativo» señala que el Movimiento Solidario y Cooperativo del Oriente Antioqueño fue uno de los sectores más golpeados por el conflicto armado. A pesar de ello, cumplió un papel protagónico al desplegar acciones de resistencia y apoyo a las comunidades desplazadas. Las cooperativas enfrentaron tomas armadas, desplazamiento forzado, confinamiento, extorsión e intimidación, pero lograron mantener su operación mediante estrategias de sostenibilidad, expansión y fortalecimiento del tejido social. Se destaca el apoyo a las personas asociadas mediante la condonación de deudas, créditos especiales y reconstrucción física de los municipios. | C7: El informe documenta que las cooperativas del Oriente Antioqueño fueron gravemente afectadas por el conflicto armado mediante desplazamientos forzados, violencia directa a empleados y asociados, y presiones de actores armados. No obstante, desempeñaron un papel clave en la resistencia civil, apoyando a comunidades desplazadas y contribuyendo a la reconstrucción del tejido social mediante estrategias económicas solidarias y acciones comunitarias. | D7: El informe revela que las cooperativas del oriente antioqueño fueron objeto de tomas armadas, desplazamiento forzado, extorsión e intimidación durante el conflicto armado, pero sobrevivieron y continuaron apoyando a sus comunidades mediante acciones de resistencia y reconstrucción. Este caso ilustra la capacidad de resistencia y adaptación del movimiento cooperativo ante las adversidades del conflicto. | E7: 41007 | F7: 721 | G7: 201
A8: ¿Qué tipo de violencia vivieron las cooperativas del Oriente Antioqueño entre 1991 y 2016 según el informe? | B8: El informe 058-CI-00662 «Memoria y construcción de paz en el sector cooperativo» detalla que las cooperativas fueron blanco de diversas acciones violentas durante el conflicto armado. Estas incluyeron asesinatos de empleados, familiares y asociados; robos e intentos de extorsión; y violencia psicológica e intimidación por parte de grupos armados. Estos actos no solo afectaron el funcionamiento de las cooperativas, sino que también contribuyeron al empobrecimiento de sus comunidades asociadas y al desplazamiento forzado masivo. | C8: Las cooperativas del Oriente Antioqueño vivieron asesinatos selectivos de su personal y asociados, robos, extorsión, amenazas e intimidación psicológica por parte de actores armados. Estas formas de violencia afectaron gravemente su funcionamiento institucional, provocaron desplazamiento forzado y contribuyeron a la descomposición del tejido social de las comunidades cooperadas. | D8: El informe documenta que las cooperativas del Oriente Antioqueño sufrieron asesinatos, robos, extorsiones y violencia psicológica por parte de grupos armados. Estas acciones afectaron directamente la actividad cooperativista y causaron desplazamiento forzado en varias localidades. | E8: 26386 | F8: 753 | G8: 272
A9: ¿Qué dice este informe 365-CI-00941 La participación de pueblos indígenas en justicia transicional - ¿oportunidad de cambios? Aprendizajes de Colombia sobre las causas estructurales del conflicto armado y sus recomendaciones para la no repetición? | B9: El informe 365-CI-00941 La participación de pueblos indígenas en justicia transicional resalta que una reconciliación multinacional, multicultural y multiétnica es esencial para asegurar la no repetición. Plantea que deben transformarse las estructuras que perpetúan la dominación étnica y que el diálogo debe incluir múltiples dimensiones socio-culturales【4:8†source】. | C9: El informe propone dialogar y revisar estructuras socio-culturales como medidas claves para la no repetición y aborda las causas estructurales del conflicto desde la perspectiva de dominación étnica y falta de reconocimiento multicultural. | D9: El informe destaca la necesidad de una reconciliación inclusiva y de transformar las estructuras que perpetúan la dominación étnica. Recomienda el diálogo intercultural e interétnico para la no repetición【4:8†source】. | E9: 24727 | F9: 691 | G9: 208
